<?xml version="1.0" encoding="UTF-8"?>
<!-- Generated by org.testng.reporters.JUnitReportReporter -->
<testsuite name="TestNGSession.EcpectedExceptionconcept" tests="1" time="0.009" ignored="0" failures="0" timestamp="22 May 2022 14:19:17 GMT" skipped="0" hostname="LAPTOP-0H005IDA" errors="1">
  <testcase name="logintest" time="0.009" classname="TestNGSession.EcpectedExceptionconcept">
    <error type="org.testng.TestException" message="
Method EcpectedExceptionconcept.logintest()[pri:0, instance:TestNGSession.EcpectedExceptionconcept@4566e5bd] should have thrown an exception of any of types [class java.lang.ArithmeticException, class java.lang.NullPointerException]">
      <![CDATA[org.testng.TestException: 
Method EcpectedExceptionconcept.logintest()[pri:0, instance:TestNGSession.EcpectedExceptionconcept@4566e5bd] should have thrown an exception of any of types [class java.lang.ArithmeticException, class java.lang.NullPointerException]
	at org.testng.internal.ExpectedExceptionsHolder.noException(ExpectedExceptionsHolder.java:89)
	at org.testng.internal.Invoker.handleInvocationResults(Invoker.java:1401)
	at org.testng.internal.Invoker.invokeMethod(Invoker.java:684)
	at org.testng.internal.Invoker.invokeTestMethod(Invoker.java:851)
	at org.testng.internal.Invoker.invokeTestMethods(Invoker.java:1177)
	at org.testng.internal.TestMethodWorker.invokeTestMethods(TestMethodWorker.java:129)
	at org.testng.internal.TestMethodWorker.run(TestMethodWorker.java:112)
	at org.testng.TestRunner.privateRun(TestRunner.java:756)
	at org.testng.TestRunner.run(TestRunner.java:610)
	at org.testng.SuiteRunner.runTest(SuiteRunner.java:387)
	at org.testng.SuiteRunner.runSequentially(SuiteRunner.java:382)
	at org.testng.SuiteRunner.privateRun(SuiteRunner.java:340)
	at org.testng.SuiteRunner.run(SuiteRunner.java:289)
	at org.testng.SuiteRunnerWorker.runSuite(SuiteRunnerWorker.java:52)
	at org.testng.SuiteRunnerWorker.run(SuiteRunnerWorker.java:86)
	at org.testng.TestNG.runSuitesSequentially(TestNG.java:1293)
	at org.testng.TestNG.runSuitesLocally(TestNG.java:1218)
	at org.testng.TestNG.runSuites(TestNG.java:1133)
	at org.testng.TestNG.run(TestNG.java:1104)
	at org.testng.remote.AbstractRemoteTestNG.run(AbstractRemoteTestNG.java:132)
	at org.testng.remote.RemoteTestNG.initAndRun(RemoteTestNG.java:236)
	at org.testng.remote.RemoteTestNG.main(RemoteTestNG.java:81)
]]>
    </error>
  </testcase> <!-- logintest -->
</testsuite> <!-- TestNGSession.EcpectedExceptionconcept -->
